Workbook

Sheet Setup
A1: 5/3/1 BBB — Setup & Training Maxes
A3: BARBELL LIFTS — All Weights Auto-Calculate & Round to Nearest 5 lb
A4: Lift | B4: True 1RM | C4: TM (90%) | D4: BBB 50% | E4: BBB 55% | F4: BBB 60% | G4: Wk1: 65% | H4: Wk1: 75% | I4: Wk1: 85% | J4: Wk2: 70% | K4: Wk2: 80% | L4: Wk2: 90% | M4: Wk3: 75% | N4: Wk3: 85% | O4: Wk3: 95%
A5: Back Squat | B5: 300 | C5: =ROUND(B5*0.9,0) -> 270 | D5: =IF(C5="","",ROUND(C5*0.5/5,0)*5) -> 135 | E5: =IF(C5="","",ROUND(C5*0.55/5,0)*5) -> 150 | F5: =IF(C5="","",ROUND(C5*0.6/5,0)*5) -> 160 | G5: =IF(C5="","",ROUND(C5*0.65/5,0)*5) -> 175 | H5: =IF(C5="","",ROUND(C5*0.75/5,0)*5) -> 205 | I5: =IF(C5="","",ROUND(C5*0.85/5,0)*5) -> 230 | J5: =IF(C5="","",ROUND(C5*0.7/5,0)*5) -> 190 | K5: =IF(C5="","",ROUND(C5*0.8/5,0)*5) -> 215 | L5: =IF(C5="","",ROUND(C5*0.9/5,0)*5) -> 245 | M5: =IF(C5="","",ROUND(C5*0.75/5,0)*5) -> 205 | N5: =IF(C5="","",ROUND(C5*0.85/5,0)*5) -> 230 | O5: =IF(C5="","",ROUND(C5*0.95/5,0)*5) -> 255
A6: Bench Press | B6: 255 | C6: =ROUND(B6*0.9,0) -> 230 | D6: =IF(C6="","",ROUND(C6*0.5/5,0)*5) -> 115 | E6: =IF(C6="","",ROUND(C6*0.55/5,0)*5) -> 125 | F6: =IF(C6="","",ROUND(C6*0.6/5,0)*5) -> 140 | G6: =IF(C6="","",ROUND(C6*0.65/5,0)*5) -> 150 | H6: =IF(C6="","",ROUND(C6*0.75/5,0)*5) -> 175 | I6: =IF(C6="","",ROUND(C6*0.85/5,0)*5) -> 195 | J6: =IF(C6="","",ROUND(C6*0.7/5,0)*5) -> 160 | K6: =IF(C6="","",ROUND(C6*0.8/5,0)*5) -> 185 | L6: =IF(C6="","",ROUND(C6*0.9/5,0)*5) -> 205 | M6: =IF(C6="","",ROUND(C6*0.75/5,0)*5) -> 175 | N6: =IF(C6="","",ROUND(C6*0.85/5,0)*5) -> 195 | O6: =IF(C6="","",ROUND(C6*0.95/5,0)*5) -> 220
A7: Deadlift | B7: 360 | C7: =ROUND(B7*0.9,0) -> 324 | D7: =IF(C7="","",ROUND(C7*0.5/5,0)*5) -> 160 | E7: =IF(C7="","",ROUND(C7*0.55/5,0)*5) -> 180 | F7: =IF(C7="","",ROUND(C7*0.6/5,0)*5) -> 195 | G7: =IF(C7="","",ROUND(C7*0.65/5,0)*5) -> 210 | H7: =IF(C7="","",ROUND(C7*0.75/5,0)*5) -> 245 | I7: =IF(C7="","",ROUND(C7*0.85/5,0)*5) -> 275 | J7: =IF(C7="","",ROUND(C7*0.7/5,0)*5) -> 225 | K7: =IF(C7="","",ROUND(C7*0.8/5,0)*5) -> 260 | L7: =IF(C7="","",ROUND(C7*0.9/5,0)*5) -> 290 | M7: =IF(C7="","",ROUND(C7*0.75/5,0)*5) -> 245 | N7: =IF(C7="","",ROUND(C7*0.85/5,0)*5) -> 275 | O7: =IF(C7="","",ROUND(C7*0.95/5,0)*5) -> 310
A8: Overhead Press | B8: 145 | C8: =ROUND(B8*0.9,0) -> 131 | D8: =IF(C8="","",ROUND(C8*0.5/5,0)*5) -> 65 | E8: =IF(C8="","",ROUND(C8*0.55/5,0)*5) -> 70 | F8: =IF(C8="","",ROUND(C8*0.6/5,0)*5) -> 80 | G8: =IF(C8="","",ROUND(C8*0.65/5,0)*5) -> 85 | H8: =IF(C8="","",ROUND(C8*0.75/5,0)*5) -> 100 | I8: =IF(C8="","",ROUND(C8*0.85/5,0)*5) -> 110 | J8: =IF(C8="","",ROUND(C8*0.7/5,0)*5) -> 90 | K8: =IF(C8="","",ROUND(C8*0.8/5,0)*5) -> 105 | L8: =IF(C8="","",ROUND(C8*0.9/5,0)*5) -> 120 | M8: =IF(C8="","",ROUND(C8*0.75/5,0)*5) -> 100 | N8: =IF(C8="","",ROUND(C8*0.85/5,0)*5) -> 110 | O8: =IF(C8="","",ROUND(C8*0.95/5,0)*5) -> 125
A10: → Enter your True 1RM in the blue cells. Everything else auto-calculates.
A12: PELOTON FTP & CARDIO ZONES
A13: Metric | B13: Value | D13: Zone | E13: Watts (low) | F13: Watts (high) | G13: Description
A14: FTP (watts) | B14: 236 | D14: Zone 2 | E14: =IF(B14="","",ROUND(B14*0.55,0)) -> 130 | F14: =IF(B14="","",ROUND(B14*0.75,0)) -> 177 | G14: Aerobic base — conversational
A15: Max Heart Rate | B15: 184 | D15: Zone 3 | E15: =IF(B14="","",ROUND(B14*0.76,0)) -> 179 | F15: =IF(B14="","",ROUND(B14*0.9,0)) -> 212 | G15: Tempo — few words only
A16: Zone 2 HR (low) | B16: =IF(B15="","",ROUND(B15*0.6,0)) -> 110 | D16: Zone 4 | E16: =IF(B14="","",ROUND(B14*0.91,0)) -> 215 | F16: =IF(B14="","",ROUND(B14*1.05,0)) -> 248 | G16: Threshold — unsustainable >30 min
A17: Zone 2 HR (high) | B17: =IF(B15="","",ROUND(B15*0.7,0)) -> 129 | D17: VO2 105% | E17: =IF(B14="","",ROUND(B14*1.05,0)) -> 248 | F17: =IF(B14="","",ROUND(B14*1.1,0)) -> 260 | G17: Interval target — Week 1-2
D18: VO2 110% | E18: =IF(B14="","",ROUND(B14*1.1,0)) -> 260 | F18: =IF(B14="","",ROUND(B14*1.15,0)) -> 271 | G18: Interval target — Week 3-5
D19: VO2 115% | E19: =IF(B14="","",ROUND(B14*1.15,0)) -> 271 | F19: =IF(B14="","",ROUND(B14*1.2,0)) -> 283 | G19: Interval target — Week 6-7
A21: BBB SUPPLEMENTAL LOAD PROGRESSION
A22: Cycle Range | B22: BBB % | C22: Squat BBB | D22: Bench BBB | E22: Dead BBB | F22: OHP BBB | G22: Notes
A23: Cycles 1–2 | B23: 50% | C23: =IF(C5="","",ROUND(C5*0.5/5,0)*5) -> 135 | D23: =IF(C6="","",ROUND(C6*0.5/5,0)*5) -> 115 | E23: =IF(C7="","",ROUND(C7*0.5/5,0)*5) -> 160 | F23: =IF(C8="","",ROUND(C8*0.5/5,0)*5) -> 65 | G23: Start here. Should feel manageable.
A24: Cycles 3–4 | B24: 55% | C24: =IF(C5="","",ROUND(C5*0.55/5,0)*5) -> 150 | D24: =IF(C6="","",ROUND(C6*0.55/5,0)*5) -> 125 | E24: =IF(C7="","",ROUND(C7*0.55/5,0)*5) -> 180 | F24: =IF(C8="","",ROUND(C8*0.55/5,0)*5) -> 70 | G24: Harder. Rest periods creep up.
A25: Cycles 5–6 | B25: 60% | C25: =IF(C5="","",ROUND(C5*0.6/5,0)*5) -> 160 | D25: =IF(C6="","",ROUND(C6*0.6/5,0)*5) -> 140 | E25: =IF(C7="","",ROUND(C7*0.6/5,0)*5) -> 195 | F25: =IF(C8="","",ROUND(C8*0.6/5,0)*5) -> 80 | G25: Very challenging. Hold during intensity cardio blocks.

Sheet Roadmap
A1: 12-MONTH ROADMAP
A3: Month | B3: Cycle | C3: Cardio Block | D3: BBB Load | E3: Squat TM | F3: Bench TM | G3: Dead TM | H3: OHP TM | I3: Notes
A4: 1 | B4: 1–2 | C4: Base A | D4: 50% | I4: Build habits. Everything moderate.
A5: 2 | B5: 2–3 | C5: Base A | D5: 50% | I5: Zone 2 volume building.
A6: 3 | B6: 3–4 | C6: Intensity A | D6: 50–55% | I6: First VO2 max block.
A7: 4 | B7: 4–5 | C7: Intensity A | D7: 55% | I7: Push interval progression.
A8: 5 | B8: 5–6 | C8: Base B | D8: 55% | I8: Consolidate aerobic gains.
A9: 6 | B9: 6–7 | C9: Base B | D9: 55–60% | I9: BBB load increasing.
A10: 7 | B10: 7–8 | C10: Intensity B | D10: 55% | I10: Hold/drop BBB during intervals.
A11: 8 | B11: 8–9 | C11: Intensity B | D11: 55% | I11: Peak interval volume.
A12: 9 | B12: 9–10 | C12: Base C | D12: 60% | I12: Push BBB load, low cardio stress.
A13: 10 | B13: 10–11 | C13: Base C | D13: 60% | I13: Strongest BBB phase.
A14: 11 | B14: 11–12 | C14: Intensity C | D14: 55% | I14: Drop BBB load, push cardio.
A15: 12 | B15: 12+ | C15: Intensity C | D15: 55% | I15: Retest all maxes & FTP.
A17: LEGEND:
A18: ■ Base Block | C18: Zone 2 only. Low stress. Push BBB load.
A19: ■ Intensity Block | C19: VO2 max intervals Wednesday. Hold/reduce BBB.

Sheet Calendar
A1: PROGRAM CALENDAR — Starting April 6, 2026
A3: Week | B3: Cycle | C3: 5/3/1 Week | D3: BBB % | E3: Cardio Block | F3: MON | G3: TUE | H3: WED | I3: THU | J3: FRI | K3: SAT | L3: SUN | M3: Notes
A4: 1 | B4: 1 | C4: Week 1 | D4: 50% | E4: Base A | F4: 04/06 Squat + BBB | G4: 04/07 Bench + BBB | H4: 04/08 Zone 2 | I4: 04/09 Deadlift + BBB | J4: 04/10 OHP + BBB | K4: 04/11 Zone 2 Long | L4: 04/12 Rest | M4: Program start
A5: 2 | B5: 1 | C5: Week 2 | D5: 50% | E5: Base A | F5: 04/13 Squat + BBB | G5: 04/14 Bench + BBB | H5: 04/15 Zone 2 | I5: 04/16 Deadlift + BBB | J5: 04/17 OHP + BBB | K5: 04/18 Zone 2 Long | L5: 04/19 Rest
A6: 3 | B6: 1 | C6: Week 3 | D6: 50% | E6: Base A | F6: 04/20 Squat + BBB | G6: 04/21 Bench + BBB | H6: 04/22 Zone 2 | I6: 04/23 Deadlift + BBB | J6: 04/24 OHP + BBB | K6: 04/25 Zone 2 Long | L6: 04/26 Rest
A7: 4 | B7: 1 | C7: Deload | D7: — | E7: Base A | F7: 04/27 Squat (deload) | G7: 04/28 Bench (deload) | H7: 04/29 Zone 2 (30 min) | I7: 04/30 Deadlift (deload) | J7: 05/01 OHP (deload) | K7: 05/02 Zone 2 (40 min) | L7: 05/03 Rest | M7: Deload. +5 lb upper / +10 lb lower TMs after.
A8: 5 | B8: 2 | C8: Week 1 | D8: 50% | E8: Base A | F8: 05/04 Squat + BBB | G8: 05/05 Bench + BBB | H8: 05/06 Zone 2 | I8: 05/07 Deadlift + BBB | J8: 05/08 OHP + BBB | K8: 05/09 Zone 2 Long | L8: 05/10 Rest
A9: 6 | B9: 2 | C9: Week 2 | D9: 50% | E9: Base A | F9: 05/11 Squat + BBB | G9: 05/12 Bench + BBB | H9: 05/13 Zone 2 | I9: 05/14 Deadlift + BBB | J9: 05/15 OHP + BBB | K9: 05/16 Zone 2 Long | L9: 05/17 Rest
A10: 7 | B10: 2 | C10: Week 3 | D10: 50% | E10: Base A | F10: 05/18 Squat + BBB | G10: 05/19 Bench + BBB | H10: 05/20 Zone 2 | I10: 05/21 Deadlift + BBB | J10: 05/22 OHP + BBB | K10: 05/23 Zone 2 Long | L10: 05/24 Rest
A11: 8 | B11: 2 | C11: Deload | D11: — | E11: Base A | F11: 05/25 Squat (deload) | G11: 05/26 Bench (deload) | H11: 05/27 Zone 2 (30 min) | I11: 05/28 Deadlift (deload) | J11: 05/29 OHP (deload) | K11: 05/30 Zone 2 (40 min) | L11: 05/31 Rest | M11: Deload. +5 lb upper / +10 lb lower TMs after.
A12: 9 | B12: 3 | C12: Week 1 | D12: 55% | E12: Intensity A | F12: 06/01 Squat + BBB | G12: 06/02 Bench + BBB | H12: 06/03 VO2 Max Intervals | I12: 06/04 Deadlift + BBB | J12: 06/05 OHP + BBB | K12: 06/06 Zone 2 Long | L12: 06/07 Rest
A13: 10 | B13: 3 | C13: Week 2 | D13: 55% | E13: Intensity A | F13: 06/08 Squat + BBB | G13: 06/09 Bench + BBB | H13: 06/10 VO2 Max Intervals | I13: 06/11 Deadlift + BBB | J13: 06/12 OHP + BBB | K13: 06/13 Zone 2 Long | L13: 06/14 Rest
A14: 11 | B14: 3 | C14: Week 3 | D14: 55% | E14: Intensity A | F14: 06/15 Squat + BBB | G14: 06/16 Bench + BBB | H14: 06/17 VO2 Max Intervals | I14: 06/18 Deadlift + BBB | J14: 06/19 OHP + BBB | K14: 06/20 Zone 2 Long | L14: 06/21 Rest
A15: 12 | B15: 3 | C15: Deload | D15: — | E15: Intensity A | F15: 06/22 Squat (deload) | G15: 06/23 Bench (deload) | H15: 06/24 Deload Ride (30 min) | I15: 06/25 Deadlift (deload) | J15: 06/26 OHP (deload) | K15: 06/27 Zone 2 (40 min) | L15: 06/28 Rest | M15: Deload. +5 lb upper / +10 lb lower TMs after.
A16: 13 | B16: 4 | C16: Week 1 | D16: 55% | E16: Intensity A | F16: 06/29 Squat + BBB | G16: 06/30 Bench + BBB | H16: 07/01 VO2 Max Intervals | I16: 07/02 Deadlift + BBB | J16: 07/03 OHP + BBB | K16: 07/04 Zone 2 Long | L16: 07/05 Rest
A17: 14 | B17: 4 | C17: Week 2 | D17: 55% | E17: Intensity A | F17: 07/06 Squat + BBB | G17: 07/07 Bench + BBB | H17: 07/08 VO2 Max Intervals | I17: 07/09 Deadlift + BBB | J17: 07/10 OHP + BBB | K17: 07/11 Zone 2 Long | L17: 07/12 Rest
A18: 15 | B18: 4 | C18: Week 3 | D18: 55% | E18: Intensity A | F18: 07/13 Squat + BBB | G18: 07/14 Bench + BBB | H18: 07/15 VO2 Max Intervals | I18: 07/16 Deadlift + BBB | J18: 07/17 OHP + BBB | K18: 07/18 Zone 2 Long | L18: 07/19 Rest
A19: 16 | B19: 4 | C19: Deload | D19: — | E19: Intensity A | F19: 07/20 Squat (deload) | G19: 07/21 Bench (deload) | H19: 07/22 Deload Ride (30 min) | I19: 07/23 Deadlift (deload) | J19: 07/24 OHP (deload) | K19: 07/25 Zone 2 (40 min) | L19: 07/26 Rest | M19: Deload. +5 lb upper / +10 lb lower TMs after.
A20: 17 | B20: 5 | C20: Week 1 | D20: 60% | E20: Base B | F20: 07/27 Squat + BBB | G20: 07/28 Bench + BBB | H20: 07/29 Zone 2 | I20: 07/30 Deadlift + BBB | J20: 07/31 OHP + BBB | K20: 08/01 Zone 2 Long | L20: 08/02 Rest
A21: 18 | B21: 5 | C21: Week 2 | D21: 60% | E21: Base B | F21: 08/03 Squat + BBB | G21: 08/04 Bench + BBB | H21: 08/05 Zone 2 | I21: 08/06 Deadlift + BBB | J21: 08/07 OHP + BBB | K21: 08/08 Zone 2 Long | L21: 08/09 Rest
A22: 19 | B22: 5 | C22: Week 3 | D22: 60% | E22: Base B | F22: 08/10 Squat + BBB | G22: 08/11 Bench + BBB | H22: 08/12 Zone 2 | I22: 08/13 Deadlift + BBB | J22: 08/14 OHP + BBB | K22: 08/15 Zone 2 Long | L22: 08/16 Rest
A23: 20 | B23: 5 | C23: Deload | D23: — | E23: Base B | F23: 08/17 Squat (deload) | G23: 08/18 Bench (deload) | H23: 08/19 Zone 2 (30 min) | I23: 08/20 Deadlift (deload) | J23: 08/21 OHP (deload) | K23: 08/22 Zone 2 (40 min) | L23: 08/23 Rest | M23: Deload. +5 lb upper / +10 lb lower TMs after.
A24: 21 | B24: 6 | C24: Week 1 | D24: 60% | E24: Base B | F24: 08/24 Squat + BBB | G24: 08/25 Bench + BBB | H24: 08/26 Zone 2 | I24: 08/27 Deadlift + BBB | J24: 08/28 OHP + BBB | K24: 08/29 Zone 2 Long | L24: 08/30 Rest
A25: 22 | B25: 6 | C25: Week 2 | D25: 60% | E25: Base B | F25: 08/31 Squat + BBB | G25: 09/01 Bench + BBB | H25: 09/02 Zone 2 | I25: 09/03 Deadlift + BBB | J25: 09/04 OHP + BBB | K25: 09/05 Zone 2 Long | L25: 09/06 Rest
A26: 23 | B26: 6 | C26: Week 3 | D26: 60% | E26: Base B | F26: 09/07 Squat + BBB | G26: 09/08 Bench + BBB | H26: 09/09 Zone 2 | I26: 09/10 Deadlift + BBB | J26: 09/11 OHP + BBB | K26: 09/12 Zone 2 Long | L26: 09/13 Rest
A27: 24 | B27: 6 | C27: Deload | D27: — | E27: Base B | F27: 09/14 Squat (deload) | G27: 09/15 Bench (deload) | H27: 09/16 Zone 2 (30 min) | I27: 09/17 Deadlift (deload) | J27: 09/18 OHP (deload) | K27: 09/19 Zone 2 (40 min) | L27: 09/20 Rest | M27: Deload. +5 lb upper / +10 lb lower TMs after.
A28: 25 | B28: 7 | C28: Week 1 | D28: 60% | E28: Intensity B | F28: 09/21 Squat + BBB | G28: 09/22 Bench + BBB | H28: 09/23 VO2 Max Intervals | I28: 09/24 Deadlift + BBB | J28: 09/25 OHP + BBB | K28: 09/26 Zone 2 Long | L28: 09/27 Rest
A29: 26 | B29: 7 | C29: Week 2 | D29: 60% | E29: Intensity B | F29: 09/28 Squat + BBB | G29: 09/29 Bench + BBB | H29: 09/30 VO2 Max Intervals | I29: 10/01 Deadlift + BBB | J29: 10/02 OHP + BBB | K29: 10/03 Zone 2 Long | L29: 10/04 Rest
A30: 27 | B30: 7 | C30: Week 3 | D30: 60% | E30: Intensity B | F30: 10/05 Squat + BBB | G30: 10/06 Bench + BBB | H30: 10/07 VO2 Max Intervals | I30: 10/08 Deadlift + BBB | J30: 10/09 OHP + BBB | K30: 10/10 Zone 2 Long | L30: 10/11 Rest
A31: 28 | B31: 7 | C31: Deload | D31: — | E31: Intensity B | F31: 10/12 Squat (deload) | G31: 10/13 Bench (deload) | H31: 10/14 Deload Ride (30 min) | I31: 10/15 Deadlift (deload) | J31: 10/16 OHP (deload) | K31: 10/17 Zone 2 (40 min) | L31: 10/18 Rest | M31: Deload. +5 lb upper / +10 lb lower TMs after.
A32: 29 | B32: 8 | C32: Week 1 | D32: 60% | E32: Intensity B | F32: 10/19 Squat + BBB | G32: 10/20 Bench + BBB | H32: 10/21 VO2 Max Intervals | I32: 10/22 Deadlift + BBB | J32: 10/23 OHP + BBB | K32: 10/24 Zone 2 Long | L32: 10/25 Rest
A33: 30 | B33: 8 | C33: Week 2 | D33: 60% | E33: Intensity B | F33: 10/26 Squat + BBB | G33: 10/27 Bench + BBB | H33: 10/28 VO2 Max Intervals | I33: 10/29 Deadlift + BBB | J33: 10/30 OHP + BBB | K33: 10/31 Zone 2 Long | L33: 11/01 Rest
A34: 31 | B34: 8 | C34: Week 3 | D34: 60% | E34: Intensity B | F34: 11/02 Squat + BBB | G34: 11/03 Bench + BBB | H34: 11/04 VO2 Max Intervals | I34: 11/05 Deadlift + BBB | J34: 11/06 OHP + BBB | K34: 11/07 Zone 2 Long | L34: 11/08 Rest
A35: 32 | B35: 8 | C35: Deload | D35: — | E35: Intensity B | F35: 11/09 Squat (deload) | G35: 11/10 Bench (deload) | H35: 11/11 Deload Ride (30 min) | I35: 11/12 Deadlift (deload) | J35: 11/13 OHP (deload) | K35: 11/14 Zone 2 (40 min) | L35: 11/15 Rest | M35: Deload. +5 lb upper / +10 lb lower TMs after.
A36: 33 | B36: 9 | C36: Week 1 | D36: 60% | E36: Base C | F36: 11/16 Squat + BBB | G36: 11/17 Bench + BBB | H36: 11/18 Zone 2 | I36: 11/19 Deadlift + BBB | J36: 11/20 OHP + BBB | K36: 11/21 Zone 2 Long | L36: 11/22 Rest
A37: 34 | B37: 9 | C37: Week 2 | D37: 60% | E37: Base C | F37: 11/23 Squat + BBB | G37: 11/24 Bench + BBB | H37: 11/25 Zone 2 | I37: 11/26 Deadlift + BBB | J37: 11/27 OHP + BBB | K37: 11/28 Zone 2 Long | L37: 11/29 Rest
A38: 35 | B38: 9 | C38: Week 3 | D38: 60% | E38: Base C | F38: 11/30 Squat + BBB | G38: 12/01 Bench + BBB | H38: 12/02 Zone 2 | I38: 12/03 Deadlift + BBB | J38: 12/04 OHP + BBB | K38: 12/05 Zone 2 Long | L38: 12/06 Rest
A39: 36 | B39: 9 | C39: Deload | D39: — | E39: Base C | F39: 12/07 Squat (deload) | G39: 12/08 Bench (deload) | H39: 12/09 Zone 2 (30 min) | I39: 12/10 Deadlift (deload) | J39: 12/11 OHP (deload) | K39: 12/12 Zone 2 (40 min) | L39: 12/13 Rest | M39: Deload. +5 lb upper / +10 lb lower TMs after.
A40: 37 | B40: 10 | C40: Week 1 | D40: 60% | E40: Base C | F40: 12/14 Squat + BBB | G40: 12/15 Bench + BBB | H40: 12/16 Zone 2 | I40: 12/17 Deadlift + BBB | J40: 12/18 OHP + BBB | K40: 12/19 Zone 2 Long | L40: 12/20 Rest
A41: 38 | B41: 10 | C41: Week 2 | D41: 60% | E41: Base C | F41: 12/21 Squat + BBB | G41: 12/22 Bench + BBB | H41: 12/23 Zone 2 | I41: 12/24 Deadlift + BBB | J41: 12/25 OHP + BBB | K41: 12/26 Zone 2 Long | L41: 12/27 Rest
...

Sheet Workout Log
A1: WEEKLY WORKOUT LOG
A3: Current Cycle #: | B3: 1 | C3: Current Week: | D3: 1 | E3: Date: | F3: 46118
A4: Wk1: 65/75/85%+ | Wk2: 70/80/90%+ | Wk3: 75/85/95%+ | Deload: 40/50/60%
A6: MONDAY — SQUAT
A7: Exercise | B7: Set | C7: Target Reps | D7: Prescribed Wt | E7: Weight Used | F7: Reps Done | G7: RPE | H7: AMRAP? | I7: Notes
A8: Warm-up | B8: 1 | C8: 5 | D8: =ROUND(Setup!C5*0.4/5,0)*5 -> 110
A9: Warm-up | B9: 2 | C9: 5 | D9: =ROUND(Setup!C5*0.5/5,0)*5 -> 135
A10: Warm-up | B10: 3 | C10: 3 | D10: =ROUND(Setup!C5*0.6/5,0)*5 -> 160
A11: Back Squat | B11: 1 | C11: =IF($D$3=1,5,IF($D$3=2,3,IF($D$3=3,5,5))) -> 5 | D11: =IF($D$3=1,ROUND(Setup!C5*0.65/5,0)*5,IF($D$3=2,ROUND(Setup!C5*0.7/5,0)*5,IF($D$3=3,ROUND(Setup!C5*0.75/5,0)*5,ROUND(Setup!C5*0.4/5,0)*5))) -> 175
A12: Back Squat | B12: 2 | C12: =IF($D$3=1,5,IF($D$3=2,3,IF($D$3=3,3,5))) -> 5 | D12: =IF($D$3=1,ROUND(Setup!C5*0.75/5,0)*5,IF($D$3=2,ROUND(Setup!C5*0.8/5,0)*5,IF($D$3=3,ROUND(Setup!C5*0.85/5,0)*5,ROUND(Setup!C5*0.5/5,0)*5))) -> 205
A13: Back Squat | B13: 3 | C13: =IF($D$3=1,"5+",IF($D$3=2,"3+",IF($D$3=3,"1+","5"))) -> 5+ | D13: =IF($D$3=1,ROUND(Setup!C5*0.85/5,0)*5,IF($D$3=2,ROUND(Setup!C5*0.9/5,0)*5,IF($D$3=3,ROUND(Setup!C5*0.95/5,0)*5,ROUND(Setup!C5*0.6/5,0)*5))) -> 230 | H13: =IF(OR($D$3=1,$D$3=2,$D$3=3),"YES","") -> YES
A14: BBB Back Squat | B14: 1/5 | C14: 10 | D14: =IF($D$3="Deload","",ROUND(Setup!C5*IF($B$3<=2,0.5,IF($B$3<=4,0.55,0.6))/5,0)*5) -> 135
B15: 2/5 | C15: 10 | D15: =IF($D$3="Deload","",ROUND(Setup!C5*IF($B$3<=2,0.5,IF($B$3<=4,0.55,0.6))/5,0)*5) -> 135
B16: 3/5 | C16: 10 | D16: =IF($D$3="Deload","",ROUND(Setup!C5*IF($B$3<=2,0.5,IF($B$3<=4,0.55,0.6))/5,0)*5) -> 135
B17: 4/5 | C17: 10 | D17: =IF($D$3="Deload","",ROUND(Setup!C5*IF($B$3<=2,0.5,IF($B$3<=4,0.55,0.6))/5,0)*5) -> 135
B18: 5/5 | C18: 10 | D18: =IF($D$3="Deload","",ROUND(Setup!C5*IF($B$3<=2,0.5,IF($B$3<=4,0.55,0.6))/5,0)*5) -> 135
A19: ACCESSORIES
A20: Chin-up | C20: 10 | D20: 5 × 10
A21: DB Lateral Raise | C21: 15 | D21: 3 × 15 | E21: 15
A22: Hanging Leg Raise | C22: 15 | D22: 3 × 15
A24: TUESDAY — BENCH PRESS
A25: Exercise | B25: Set | C25: Target Reps | D25: Prescribed Wt | E25: Weight Used | F25: Reps Done | G25: RPE | H25: AMRAP? | I25: Notes
A26: Warm-up | B26: 1 | C26: 5 | D26: =ROUND(Setup!C6*0.4/5,0)*5 -> 90
A27: Warm-up | B27: 2 | C27: 5 | D27: =ROUND(Setup!C6*0.5/5,0)*5 -> 115
A28: Warm-up | B28: 3 | C28: 3 | D28: =ROUND(Setup!C6*0.6/5,0)*5 -> 140
A29: Bench Press | B29: 1 | C29: =IF($D$3=1,5,IF($D$3=2,3,IF($D$3=3,5,5))) -> 5 | D29: =IF($D$3=1,ROUND(Setup!C6*0.65/5,0)*5,IF($D$3=2,ROUND(Setup!C6*0.7/5,0)*5,IF($D$3=3,ROUND(Setup!C6*0.75/5,0)*5,ROUND(Setup!C6*0.4/5,0)*5))) -> 150
A30: Bench Press | B30: 2 | C30: =IF($D$3=1,5,IF($D$3=2,3,IF($D$3=3,3,5))) -> 5 | D30: =IF($D$3=1,ROUND(Setup!C6*0.75/5,0)*5,IF($D$3=2,ROUND(Setup!C6*0.8/5,0)*5,IF($D$3=3,ROUND(Setup!C6*0.85/5,0)*5,ROUND(Setup!C6*0.5/5,0)*5))) -> 175
A31: Bench Press | B31: 3 | C31: =IF($D$3=1,"5+",IF($D$3=2,"3+",IF($D$3=3,"1+","5"))) -> 5+ | D31: =IF($D$3=1,ROUND(Setup!C6*0.85/5,0)*5,IF($D$3=2,ROUND(Setup!C6*0.9/5,0)*5,IF($D$3=3,ROUND(Setup!C6*0.95/5,0)*5,ROUND(Setup!C6*0.6/5,0)*5))) -> 195 | H31: =IF(OR($D$3=1,$D$3=2,$D$3=3),"YES","") -> YES
A32: BBB Bench Press | B32: 1/5 | C32: 10 | D32: =IF($D$3="Deload","",ROUND(Setup!C6*IF($B$3<=2,0.5,IF($B$3<=4,0.55,0.6))/5,0)*5) -> 115
B33: 2/5 | C33: 10 | D33: =IF($D$3="Deload","",ROUND(Setup!C6*IF($B$3<=2,0.5,IF($B$3<=4,0.55,0.6))/5,0)*5) -> 115
B34: 3/5 | C34: 10 | D34: =IF($D$3="Deload","",ROUND(Setup!C6*IF($B$3<=2,0.5,IF($B$3<=4,0.55,0.6))/5,0)*5) -> 115
B35: 4/5 | C35: 10 | D35: =IF($D$3="Deload","",ROUND(Setup!C6*IF($B$3<=2,0.5,IF($B$3<=4,0.55,0.6))/5,0)*5) -> 115
B36: 5/5 | C36: 10 | D36: =IF($D$3="Deload","",ROUND(Setup!C6*IF($B$3<=2,0.5,IF($B$3<=4,0.55,0.6))/5,0)*5) -> 115
A37: ACCESSORIES
A38: Single-arm DB row | C38: 10 | D38: 5 × 10
A39: Incline DB Bench Press | C39: 10 | D39: 5 × 10
A40: Prone Y Raise | C40: 15 | D40: 3 × 15 | E40: 5
A42: THURSDAY — DEADLIFT
A43: Exercise | B43: Set | C43: Target Reps | D43: Prescribed Wt | E43: Weight Used | F43: Reps Done | G43: RPE | H43: AMRAP? | I43: Notes
A44: Warm-up | B44: 1 | C44: 5 | D44: =ROUND(Setup!C7*0.4/5,0)*5 -> 130
...

Sheet Cardio Log
A1: CARDIO LOG
A3: WEDNESDAY — VO2 MAX / ZONE 2
A4: Date | B4: Block | C4: Session Type | D4: Duration | E4: Intervals | F4: Avg Power | G4: Avg HR | H4: Difficulty | I4: Notes
A5: 46120 | B5: Base | C5: Zone 2 | E5: N/A
A6: =A5+7 -> 46127 | B6: Base | C6: Zone 2 | E6: N/A
A7: =A6+7 -> 46134 | B7: Base | C7: Zone 2 | E7: N/A
A8: =A7+7 -> 46141 | B8: Base | C8: Deload Ride | E8: N/A
A9: =A8+7 -> 46148 | B9: Base | C9: Zone 2 | E9: N/A
A10: =A9+7 -> 46155 | B10: Base | C10: Zone 2 | E10: N/A
A11: =A10+7 -> 46162 | B11: Base | C11: Zone 2 | E11: N/A
A12: =A11+7 -> 46169 | B12: Base | C12: Deload Ride | E12: N/A
A13: =A12+7 -> 46176 | B13: Intensity | C13: VO2 Max Intervals
A14: =A13+7 -> 46183 | B14: Intensity | C14: VO2 Max Intervals
A15: =A14+7 -> 46190 | B15: Intensity | C15: VO2 Max Intervals
A16: =A15+7 -> 46197 | B16: Intensity | C16: Deload Ride | E16: N/A
A17: =A16+7 -> 46204 | B17: Intensity | C17: VO2 Max Intervals
A18: =A17+7 -> 46211 | B18: Intensity | C18: VO2 Max Intervals
A19: =A18+7 -> 46218 | B19: Intensity | C19: VO2 Max Intervals
A20: =A19+7 -> 46225 | B20: Intensity | C20: Deload Ride | E20: N/A
A21: =A20+7 -> 46232 | B21: Base | C21: Zone 2 | E21: N/A
A22: =A21+7 -> 46239 | B22: Base | C22: Zone 2 | E22: N/A
A23: =A22+7 -> 46246 | B23: Base | C23: Zone 2 | E23: N/A
A24: =A23+7 -> 46253 | B24: Base | C24: Deload Ride | E24: N/A
A27: SATURDAY — AEROBIC DEVELOPMENT
A28: Date | B28: Type | C28: Duration | D28: Avg HR | E28: Avg Power | F28: Distance | G28: Difficulty | H28: RHR Today | I28: Notes
A29: 46123 | B29: Zone 2 Long
A30: =A29+7 -> 46130 | B30: Zone 2 Long
A31: =A30+7 -> 46137 | B31: Zone 2 Long
A32: =A31+7 -> 46144 | B32: Deload Easy
A33: =A32+7 -> 46151 | B33: Zone 2 Long
A34: =A33+7 -> 46158 | B34: Zone 2 Long
A35: =A34+7 -> 46165 | B35: Zone 2 Long
A36: =A35+7 -> 46172 | B36: Deload Easy
A37: =A36+7 -> 46179 | B37: Zone 2 Long
A38: =A37+7 -> 46186 | B38: Zone 2 Long
A39: =A38+7 -> 46193 | B39: Zone 2 Long
A40: =A39+7 -> 46200 | B40: Deload Easy
A41: =A40+7 -> 46207 | B41: Zone 2 Long
... A48: =A47+7 -> 46256 | B48: Deload Easy

Sheet Progress
A1: PROGRESS DASHBOARD
A3: AMRAP RESULTS & ESTIMATED 1RM — Log Week 3 Top Set Each Cycle
A4: Cycle | B4: Date | C4: Squat Wt | D4: Squat Reps | E4: Squat e1RM | F4: Bench Wt | G4: Bench Reps | H4: Bench e1RM | I4: Dead Wt | J4: Dead Reps | K4: Dead e1RM
A5: 1 | E5: =IF(OR(C5="",D5=""),"",ROUND(C5*(1+D5*0.0333),0)) | H5: =IF(OR(F5="",G5=""),"",ROUND(F5*(1+G5*0.0333),0)) | K5: =IF(OR(I5="",J5=""),"",ROUND(I5*(1+J5*0.0333),0))
A6: 2 | E6: =IF(OR(C6="",D6=""),"",ROUND(C6*(1+D6*0.0333),0)) | H6: =IF(OR(F6="",G6=""),"",ROUND(F6*(1+G6*0.0333),0)) | K6: =IF(OR(I6="",J6=""),"",ROUND(I6*(1+J6*0.0333),0))
A7: 3 | E7: =IF(OR(C7="",D7=""),"",ROUND(C7*(1+D7*0.0333),0)) | H7: =IF(OR(F7="",G7=""),"",ROUND(F7*(1+G7*0.0333),0)) | K7: =IF(OR(I7="",J7=""),"",ROUND(I7*(1+J7*0.0333),0))
A8: 4 | E8: =IF(OR(C8="",D8=""),"",ROUND(C8*(1+D8*0.0333),0)) | H8: =IF(OR(F8="",G8=""),"",ROUND(F8*(1+G8*0.0333),0)) | K8: =IF(OR(I8="",J8=""),"",ROUND(I8*(1+J8*0.0333),0))
A9: 5 | E9: =IF(OR(C9="",D9=""),"",ROUND(C9*(1+D9*0.0333),0)) | H9: =IF(OR(F9="",G9=""),"",ROUND(F9*(1+G9*0.0333),0)) | K9: =IF(OR(I9="",J9=""),"",ROUND(I9*(1+J9*0.0333),0))
A10: 6 | E10: =IF(OR(C10="",D10=""),"",ROUND(C10*(1+D10*0.0333),0)) | H10: =IF(OR(F10="",G10=""),"",ROUND(F10*(1+G10*0.0333),0)) | K10: =IF(OR(I10="",J10=""),"",ROUND(I10*(1+J10*0.0333),0))
A11: 7 | E11: =IF(OR(C11="",D11=""),"",ROUND(C11*(1+D11*0.0333),0)) | H11: =IF(OR(F11="",G11=""),"",ROUND(F11*(1+G11*0.0333),0)) | K11: =IF(OR(I11="",J11=""),"",ROUND(I11*(1+J11*0.0333),0))
A12: 8 | E12: =IF(OR(C12="",D12=""),"",ROUND(C12*(1+D12*0.0333),0)) | H12: =IF(OR(F12="",G12=""),"",ROUND(F12*(1+G12*0.0333),0)) | K12: =IF(OR(I12="",J12=""),"",ROUND(I12*(1+J12*0.0333),0))
A13: 9 | E13: =IF(OR(C13="",D13=""),"",ROUND(C13*(1+D13*0.0333),0)) | H13: =IF(OR(F13="",G13=""),"",ROUND(F13*(1+G13*0.0333),0)) | K13: =IF(OR(I13="",J13=""),"",ROUND(I13*(1+J13*0.0333),0))
A14: 10 | E14: =IF(OR(C14="",D14=""),"",ROUND(C14*(1+D14*0.0333),0)) | H14: =IF(OR(F14="",G14=""),"",ROUND(F14*(1+G14*0.0333),0)) | K14: =IF(OR(I14="",J14=""),"",ROUND(I14*(1+J14*0.0333),0))
A15: 11 | E15: =IF(OR(C15="",D15=""),"",ROUND(C15*(1+D15*0.0333),0)) | H15: =IF(OR(F15="",G15=""),"",ROUND(F15*(1+G15*0.0333),0)) | K15: =IF(OR(I15="",J15=""),"",ROUND(I15*(1+J15*0.0333),0))
A16: 12 | E16: =IF(OR(C16="",D16=""),"",ROUND(C16*(1+D16*0.0333),0)) | H16: =IF(OR(F16="",G16=""),"",ROUND(F16*(1+G16*0.0333),0)) | K16: =IF(OR(I16="",J16=""),"",ROUND(I16*(1+J16*0.0333),0))
... A20: 16 | E20: =IF(OR(C20="",D20=""),"",ROUND(C20*(1+D20*0.0333),0)) | H20: =IF(OR(F20="",G20=""),"",ROUND(F20*(1+G20*0.0333),0)) | K20: =IF(OR(I20="",J20=""),"",ROUND(I20*(1+J20*0.0333),0))
A22: OHP AMRAP RESULTS | G22: FTP TEST RESULTS
A23: Cycle | B23: Date | C23: OHP Wt | D23: OHP Reps | E23: OHP e1RM | G23: Test # | H23: Date | I23: FTP (W) | J23: Change (W) | K23: Before Block
A24: 1 | E24: =IF(OR(C24="",D24=""),"",ROUND(C24*(1+D24*0.0333),0)) | G24: 1 | J24: —
A25: 2 | E25: =IF(OR(C25="",D25=""),"",ROUND(C25*(1+D25*0.0333),0)) | G25: 2 | J25: =IF(OR(I25="",I24=""),"",I25-I24)
A26: 3 | E26: =IF(OR(C26="",D26=""),"",ROUND(C26*(1+D26*0.0333),0)) | G26: 3 | J26: =IF(OR(I26="",I25=""),"",I26-I25)
A27: 4 | E27: =IF(OR(C27="",D27=""),"",ROUND(C27*(1+D27*0.0333),0)) | G27: 4 | J27: =IF(OR(I27="",I26=""),"",I27-I26)
A28: 5 | E28: =IF(OR(C28="",D28=""),"",ROUND(C28*(1+D28*0.0333),0)) | G28: 5 | J28: =IF(OR(I28="",I27=""),"",I28-I27)
A29: 6 | E29: =IF(OR(C29="",D29=""),"",ROUND(C29*(1+D29*0.0333),0)) | G29: 6 | J29: =IF(OR(I29="",I28=""),"",I29-I28)
A30: 7 | E30: =IF(OR(C30="",D30=""),"",ROUND(C30*(1+D30*0.0333),0)) | G30: 7 | J30: =IF(OR(I30="",I29=""),"",I30-I29)
A31: 8 | E31: =IF(OR(C31="",D31=""),"",ROUND(C31*(1+D31*0.0333),0)) | G31: 8 | J31: =IF(OR(I31="",I30=""),"",I31-I30)
A32: 9 | E32: =IF(OR(C32="",D32=""),"",ROUND(C32*(1+D32*0.0333),0))
A33: 10 | E33: =IF(OR(C33="",D33=""),"",ROUND(C33*(1+D33*0.0333),0))
A34: 11 | E34: =IF(OR(C34="",D34=""),"",ROUND(C34*(1+D34*0.0333),0))
A35: 12 | E35: =IF(OR(C35="",D35=""),"",ROUND(C35*(1+D35*0.0333),0))
A36: 13 | E36: =IF(OR(C36="",D36=""),"",ROUND(C36*(1+D36*0.0333),0))
A37: 14 | E37: =IF(OR(C37="",D37=""),"",ROUND(C37*(1+D37*0.0333),0))
A38: 15 | E38: =IF(OR(C38="",D38=""),"",ROUND(C38*(1+D38*0.0333),0))
A39: 16 | E39: =IF(OR(C39="",D39=""),"",ROUND(C39*(1+D39*0.0333),0))
A41: AMRAP HEALTH CHECK (Week 3 top set at 95% TM):
A42: 5+ reps = TM is perfect. Keep progressing.
A43: 3–4 reps = TM is slightly high. Watch next cycle.
A44: 1–2 reps = TM is too high. Reduce by 10% and rebuild.
